<mujoco model="bruce">
  <compiler eulerseq="XYZ" angle="degree" meshdir="meshes"/> 
  <default>
    <default class="unused"/>
    <default class="bear">
      <joint armature="0.1" damping="0.1" stiffness="0.0" frictionloss="0.0"/>
      <position timeconst="0.00" forcerange="-12 12"/>
      <velocity forcerange="-12 12"/>
    </default>
    <default class="dynamixel">
      <joint damping="10.084" armature="0.5" frictionloss="0.03"/>
    </default>
    <default class="friction_body">
      <geom friction="1.0 0.005 0.0001"/>
    </default>
    <joint limited="true"/>
    <equality solimp="0.0 0.95 0.0001 0.1 2" solref="0.005 0.5"/>
  </default>
  <visual>
      <!-- <headlight ambient="0.5         0.5         0.5"/> -->
      <!-- <headlight diffuse="0.6 0.6 0.6" ambient="0.3 0.3 0.3" specular="0 0 0"/> -->
      <!-- <headlight diffuse=".8 .8 .8" ambient=".2 .2 .2" specular="1 1 1"/> -->
      <headlight diffuse="0.6 0.6 0.6" ambient="0.6 0.6 0.6" specular="1 1 1"/>
      <map force="0.1"/>
      <!-- <rgba haze="0.15 0.25 0.35 1" contactforce="0.7 0.9 0.9 0.5"/> -->
      <global offwidth="3000" offheight="3000"/>
      <scale forcewidth="0.2"/>
      <quality offsamples="4"/>
   </visual>
  <option gravity="0 0 -9.81"
        integrator="Euler"
        iterations="3"
        ls_iterations="6"
        solver="Newton"
        timestep="0.001"
        cone="pyramidal">
    <flag eulerdamp="disable"/>
  </option>
  <asset>
    <!-- <texture name="grid" type="2d" builtin="checker" rgb1="0.10000000000000001 0.20000000000000001 0.29999999999999999" rgb2="0.20000000000000001 0.29999999999999999 0.40000000000000002" width="512" height="512"/> -->
    <!-- <material name="grid" class="unused" texture="grid" texrepeat="1 1" texuniform="true" reflectance="0.20000000000000001"/> -->
    <texture type="skybox" builtin="gradient" rgb1="1 1 1" rgb2="1 1 1" width="800" height="800"/>
    <texture type="2d" name="groundplane" builtin="checker" mark="edge" rgb1="1 1 1" rgb2="1 1 1"
      markrgb="0 0 0" width="300" height="300"/>
    <texture type="2d" name="groundplane2" builtin="checker" mark="edge" rgb1="1 1 1" rgb2="1 1 1"
      markrgb="1 1 1" width="300" height="300"/>
    <material name="groundplane" texture="groundplane" texuniform="true" texrepeat="5 5" reflectance="0"/>
    <mesh name="base_link" class="unused" file="base_link-33173c89ec846a4cd9f57a66c66a1e54bd3853e5.STL" scale="1 1 1"/>
    <mesh name="hip_yaw_link_r" class="unused" file="hip_yaw_link_r-a15bcb335452d8100d40540abde17b87aad4009f.STL" scale="1 1 1"/>
    <mesh name="hip_pitch_link_r" class="unused" file="hip_pitch_link_r-ed7cab1d1821343307d7796d5f710e7bb63439af.STL" scale="1 1 1"/>
    <mesh name="hip_roll_link_r" class="unused" file="hip_roll_link_r-a100f7dbb76ed20e366f73ec538b9f9470f751e7.STL" scale="1 1 1"/>
    <mesh name="knee_pitch_link_r" class="unused" file="knee_pitch_link_r-007eee94201e0ddf45b29c37a3282aa85b0eff2c.STL" scale="1 1 1"/>
    <mesh name="ankle_pitch_link_r" class="unused" file="ankle_pitch_link_r-3ee539500ddfe21a0dee0be93986fb6bb256abef.STL" scale="1 1 1"/>
    <mesh name="hip_yaw_link_l" class="unused" file="hip_yaw_link_l-26a3618fd9779e7639bbe5d4af05dd495293294f.STL" scale="1 1 1"/>
    <mesh name="hip_pitch_link_l" class="unused" file="hip_pitch_link_l-0e4898852d181ac4196abcc176ebdd8d0e9e3465.STL" scale="1 1 1"/>
    <mesh name="hip_roll_link_l" class="unused" file="hip_roll_link_l-7aabeb383808bb7264aadb6ea7b9de35f697ddf6.STL" scale="1 1 1"/>
    <mesh name="knee_pitch_link_l" class="unused" file="knee_pitch_link_l-8b7fc199690bcbd6d77d67ff3103c985eeec4dd4.STL" scale="1 1 1"/>
    <mesh name="ankle_pitch_link_l" class="unused" file="ankle_pitch_link_l-28b2e007cadfd9b863a2e610a4c39930a688100e.STL" scale="1 1 1"/>
    <mesh name="shoulder_pitch_link_r" class="unused" file="shoulder_pitch_link_r-bfff8bc12770d88d60ce2c36a94e0c6c85c28756.STL" scale="1 1 1"/>
    <mesh name="shoulder_roll_link_r" class="unused" file="shoulder_roll_link_r-f75f630b2b3b4faedd8f37fbbaee9af8335e50dc.STL" scale="1 1 1"/>
    <mesh name="elbow_pitch_link_r" class="unused" file="elbow_pitch_link_r-fb6ecb102d6f01ddf8b05393ca62437a6e87090d.STL" scale="1 1 1"/>
    <mesh name="shoulder_pitch_link_l" class="unused" file="shoulder_pitch_link_l-6587e918134a055d3755296e90193444d45861b8.STL" scale="1 1 1"/>
    <mesh name="shoulder_roll_link_l" class="unused" file="shoulder_roll_link_l-d4feb2623b729b5af2075ca5b24ad625e94a79c2.STL" scale="1 1 1"/>
    <mesh name="elbow_pitch_link_l" class="unused" file="elbow_pitch_link_l-18c3dc9c62df978894c899f9f6d50c979d586f95.STL" scale="1 1 1"/>
    <mesh name="ankle_drive_arm_l" class="unused" file="ankle_drive_arm_l.STL" scale="1 1 1"/>
    <mesh name="ankle_drive_arm_r" class="unused" file="ankle_drive_arm_r.STL" scale="1 1 1"/>

    <!-- <texture type="2d" name="groundplane" builtin="checker" mark="edge" rgb1="0.2 0.3 0.4" rgb2="0.1 0.2 0.3" -->
      <!-- markrgb="0.8 0.8 0.8" width="300" height="300"/> -->
    <!-- <material name="groundplane" texture="groundplane" texuniform="true" texrepeat="5 5" reflectance="0.2"/> -->
  </asset>
  <worldbody>
    <!-- <geom name="floor" class="unused" type="plane" condim="3" size="0 0 0.050000000000000003" material="grid" pos="0 0 0"/> -->
    <!-- <light pos="0 0 2.5" dir="-1 -1 -1" directional="true"/> -->
    <camera name='top_view' pos="1.5 -0.25 4.0" xyaxes="1.0 0.0 0.0 0.0 1.0 0.0"/>
    <camera name='top_side' pos="1.352 -4.249 2.869" xyaxes="1.000 0.014 -0.000 -0.006 0.440 0.898"/>
    <!-- <camera name='side' pos="1.783 -2.318 0.978" xyaxes="0.977 0.214 -0.000 -0.049 0.225 0.973"/> -->
    <!-- <camera name='side' pos="2.028 -1.652 0.990" xyaxes="0.960 0.282 0.000 -0.072 0.244 0.967"/> -->
    <!-- <camera name='side' pos="1.334 -1.404 0.903" xyaxes="0.990 0.139 -0.000 -0.034 0.243 0.969"/> -->
    <!-- <camera name='side' pos="1.250 -1.413 0.896" xyaxes="0.994 0.106 0.000 -0.026 0.244 0.969"/> -->
    <camera name = 'side' pos="1.011 -1.418 0.926" xyaxes="1.000 -0.001 0.000 0.000 0.258 0.966"/>
    <!-- <camera name='front' pos="1.472 -0.349 0.820" xyaxes="-0.008 1.000 -0.000 -0.333 -0.003 0.943"/> -->
    <camera name='front' pos="1.1 -0.3 0.75" xyaxes="0.004 1.000 0.000 -0.284 0.001 0.959"/>







    <geom name="plane" class="friction_body" pos="9 0 0" size="10 2 0.05" type="plane" condim="3" material="groundplane"/>
    <body name="base_link" pos="0 0 0.4728" euler="0 -0 0">
    <light name="headlight" pos="2 2 10" dir="-2 -2 -10" diffuse="0.7 0.7 0.7" specular="0.3 0.3 0.3" directional="false"/>
    <!-- <light pos="3.5 0 6" dir="0 0 -10" diffuse="1 1 1" specular="0.3 0.3 0.3" directional="false"/> -->
    <!-- <light pos="0 5 6" dir="0 0 -10" diffuse="1 1 1" specular="0.3 0.3 0.3" directional="false"/> -->

    <camera name="track" pos="1.1 -1.1 0.5" xyaxes="0.7 0.700 0.000 -0.171 0.296 0.940" mode="trackcom"/>
      <inertial pos="0.022596000000000002 -0.000113 0.061400999999999997" mass="1.6168899999999999" fullinertia="0.0133543 0.0102363 0.0054710000000000002 -3.36e-06 0.0018272500000000001 -1.163e-05"/>
      <!-- <geom name="base_link_collision" class="unused" type="mesh" group="3" friction="1 0.0050000000000000001 0.0001" pos="0 0 0" euler="0 -0 0" mesh="base_link"/> -->
      <site name="base_IMU" pos="0 0 0" euler="0 0 0" size="0.01" rgba="1 0 0 0.0" type="sphere"/>
      <geom name="base_link_visual" class="unused" type="mesh" contype="0" conaffinity="0" group="0" pos="0 0 0" euler="0 -0 0" mesh="base_link"/>
      <freejoint name="freejoint"/>
      <body name="hip_yaw_link_r" pos="0.029215999999999999 -0.075856000000000007 -0.039765000000000002" euler="0 0 -90.000210459149713">
        <inertial pos="3.0000000000000001e-06 -0.00024800000000000001 0.0052240000000000003" mass="0.63756299999999999" fullinertia="0.00048540999999999998 0.00161689 0.00152129 1.1200000000000001e-06 1.7400000000000001e-06 -7.0199999999999997e-06"/>
        <!-- <geom name="hip_yaw_link_r_collision" class="unused" type="mesh" group="3" friction="1 0.0050000000000000001 0.0001" pos="1.3877787807814457e-17 2.4286128663675299e-17 -6.9388939039072284e-18" euler="0 -0 0" mesh="hip_yaw_link_r"/> -->
        <geom name="hip_yaw_link_r_visual" class="unused" type="mesh" contype="0" conaffinity="0" group="0" pos="1.3877787807814457e-17 2.4286128663675299e-17 -6.9388939039072284e-18" euler="0 -0 0" mesh="hip_yaw_link_r"/>
        <joint name="hip_yaw_r" class="bear" type="hinge" pos="1.3877787807814457e-17 2.4286128663675299e-17 -6.9388939039072284e-18" axis="0 0 1" limited="true" range="-179.99469134034814 179.99469134034814"  />
        <body name="hip_pitch_link_r" pos="1.3877787807814457e-17 2.4286128663675299e-17 -6.9388939039072284e-18" euler="179.99999999755093 89.999789541765594 179.99999999755093">
          <inertial pos="0 6.9999999999999999e-06 0" mass="0.050000000000000003" fullinertia="1.0000000000000001e-05 1.0000000000000001e-05 1.0000000000000001e-05 0 0 0"/>
          <!-- <geom name="hip_pitch_link_r_collision" class="unused" type="mesh" group="3" friction="1 0.0050000000000000001 0.0001" pos="0 4.8572257327350599e-17 4.163336342344337e-17" euler="0 -0 0" mesh="hip_pitch_link_r"/> -->
          <geom name="hip_pitch_link_r_visual" class="unused" type="mesh" contype="0" conaffinity="0" group="0" pos="0 4.8572257327350599e-17 4.163336342344337e-17" euler="0 -0 0" mesh="hip_pitch_link_r"/>
          <joint name="hip_pitch_r" class="bear" type="hinge" pos="0 4.8572257327350599e-17 4.163336342344337e-17" axis="0 0 1" limited="true" range="-179.99469134034814 179.99469134034814"  />
          <body name="hip_roll_link_r" pos="0 4.8572257327350599e-17 4.163336342344337e-17" euler="-90.000210459149713 -2.6039853883801605e-15 -1.5387972356333047e-14">
            <inertial pos="0.13900000000000001 0.00037300000000000001 -0.0064900000000000001" mass="0.66351899999999997" fullinertia="0.00044200000000000001 0.016 0.015699999999999999 7.2899999999999997e-05 -0.00029100000000000003 1.11e-06"/>
            <!-- <geom name="hip_roll_link_r_collision" class="unused" type="mesh" group="3" friction="1 0.0050000000000000001 0.0001" pos="0 -1.3877787807814457e-17 3.8163916471489756e-17" euler="0 -1.6810236079381462e-15 0" mesh="hip_roll_link_r"/> -->
            <geom name="hip_roll_link_r_visual" class="unused" type="mesh" contype="0" conaffinity="0" group="0" pos="0 -1.3877787807814457e-17 3.8163916471489756e-17" euler="0 -1.6810236079381462e-15 0" mesh="hip_roll_link_r"/>
            <joint name="hip_roll_r" class="bear" type="hinge" pos="0 0 0" axis="0 0 1" limited="true" range="-179.99 179.99"  />
            <body name="knee_pitch_link_r" pos="0.20494899999999999 0 0" euler="90.0 0 0">
              <inertial pos="0.072931 0.017464 0.002164" mass="0.0956654" fullinertia="0.00010962 0.0010194100000000001 0.0010831700000000001 5.2800000000000003e-05 1.5699999999999999e-05 -6.6800000000000004e-06"/>
              <!-- <geom name="knee_pitch_link_r_collision" class="unused" type="mesh" group="3" friction="1 0.0050000000000000001 0.0001" pos="2.2204460492503131e-16 9.0205620750793969e-17 3.0531133177191805e-16" euler="0 0 -3.1805546814635168e-15" mesh="knee_pitch_link_r"/> -->
              <geom name="knee_pitch_link_r_visual" class="unused" type="mesh" contype="0" conaffinity="0" group="0" pos="2.2204460492503131e-16 9.0205620750793969e-17 3.0531133177191805e-16" euler="0 0 -3.1805546814635168e-15" mesh="knee_pitch_link_r"/>
              <joint name="knee_pitch_r" class="bear" type="hinge" pos="2.2204460492503131e-16 9.0205620750793969e-17 3.0531133177191805e-16" axis="0 0 1" limited="true" range="-179.99469134034814 -0.57295779513082323"  />
              <body name="ankle_pitch_link_r" pos="0.19988100000000017 8.3266726846886741e-17 2.7755575615628914e-16" euler="0 0 -3.1805546814635168e-15">
                <inertial pos="0.012078 0.0019750000000000002 0.00029500000000000001" mass="0.027626499999999998" fullinertia="2.0400000000000001e-05 6.1999999999999999e-06 2.5899999999999999e-05 2.8700000000000001e-06 -2.9999999999999997e-08 -2.3999999999999998e-07"/>
                <!-- <geom name="ankle_pitch_link_r_collision" class="unused" type="mesh" group="3" friction="1 0.0050000000000000001 0.0001" pos="3.8857805861880479e-16 1.3877787807814457e-16 5.2735593669694936e-16" euler="0 0 -3.1805546814635168e-15" mesh="ankle_pitch_link_r"/> -->
                <!-- <geom name="toe_right_collision" class="friction_body"  rgba="1 0 0 1" type="sphere" size="0.0050000000000000001"  pos="0.02500000000000039 0.050000000000000142 5.2735593669694936e-16" euler="0 0 -3.1805546814635168e-15"/> -->
                <!-- <geom name="heel_right_collision" class="friction_body"  type="sphere" group="3" size="0.0050000000000000001" pos="0.02500000000000039 -0.034999999999999865 5.2735593669694936e-16" euler="0 0 -3.1805546814635168e-15"/> -->
                <!-- <geom name="r_collision_fl" class="friction_body" type="sphere" group="0" size="0.001" pos="0.024  0.055   0.014" euler="0 0 0"/> -->
                <!-- <geom name="r_collision_bl" class="friction_body" type="sphere" group="0" size="0.001" pos="0.024 -0.045  0.014" euler="0 0 0"/> -->
                <!-- <geom name="r_collision_fr" class="friction_body" type="sphere" group="0" size="0.001" pos="0.024  0.055  -0.014" euler="0 0 0"/> -->
                <!-- <geom name="r_collision_br" class="friction_body" type="sphere" group="0" size="0.001" pos="0.024 -0.045 -0.014" euler="0 0 0"/> -->
                <geom name="right_foot_collision" class="friction_body" type="box" size="0.0515 0.014 0.0035" pos="0.0215 0.005 0.0" euler="90 0 90"/>
                <geom name="ankle_pitch_link_r_visual" class="unused" type="mesh" contype="0" conaffinity="0"  group="0" pos="3.8857805861880479e-16 1.3877787807814457e-16 5.2735593669694936e-16" euler="0 0 -3.1805546814635168e-15" mesh="ankle_pitch_link_r"/>
                <site name="0" size="0.02" group="3" class="unused" pos="0.02500000000000039 0.050000000000000142 5.2735593669694936e-16" euler="0 0 -3.1805546814635168e-15"/>
                <site name="midfoot_r" pos="0.025 0.0 0.0" rgba="0 1 0 0" size="0.01" type="sphere"/>
                <site name="1" size="0.02" group="3" class="unused" pos="0.02500000000000039 -0.034999999999999865 5.2735593669694936e-16" euler="0 0 -3.1805546814635168e-15"/>
                <joint name="ankle_pitch_r" class="bear" type="hinge" pos="3.8857805861880479e-16 1.3877787807814457e-16 5.2735593669694936e-16" axis="0 0 1" limited="true" range="-179.99469134034814 179.99469134034814"  />
                <body name="achilles_rod_r" pos="0 -0.03 0" euler="0 0 0">
                  <inertial pos="-0.1 0.0 0.0" mass="0.00550849" diaginertia="5.3485e-8 1e-4 1e-4"/>
                  <joint name="ankle_achilles_jt_r" class="bear" type="hinge" pos="0 0 0" axis="0 0 1" limited="true" range="-179.99469134034814 179.99469134034814"/>
                  <geom name="achilles_rod_r" class="unused"  type="cylinder" size="0.006" fromto="0.0 0.0 0.0 -0.2 0.0 0.0" euler="90 0 90" contype="0" conaffinity="0"/>
                  <site name="achilles_attach_r" group="3" pos="-0.2 0.0 0.0"  size="0.01" type="sphere"/>
                </body>
              </body>
            </body>
            <body name="ankle_drive_arm_r" pos="0.204949 0.0 0.0" euler="90.0 0 0">
                <!-- The geom for visualization is offset to the side to look like the real robot, but the mechanism is defined in the midplane of the foot to avoid having to create ball joints -->
                <geom name="ankle_pitch_drive_arm_r_visual" class="unused" contype="0" conaffinity="0" type="mesh" group="0" pos="0 0 0.02625" euler="0 0 40" mesh="ankle_drive_arm_r"/>
                <inertial pos="0.00052293  0.00264346 0.00113556" mass="0.00832597" fullinertia="1.2724e-6 4.1068e-7 1.6054e-6 7.1971e-8 9.7107e-9 4.3047e-8"/>
                <joint name="ankle_crank_r" class="bear" type="hinge" pos="0 0 0" axis="0 0 1" limited="true" range="-179.99469134034814 179.99469134034814"  />
                <site name="ankle_upper_attach_r" group="0" pos="0.0 -0.03 0.0"  size="0.01" type="sphere"/>
            </body>
          </body>
        </body>
      </body>
      <body name="hip_yaw_link_l" pos="0.029215999999999999 0.075856000000000007 -0.039765000000000002" euler="0 0 -90.000210459149713">
        <inertial pos="0 -0.00020799999999999999 0.00528" mass="0.63738600000000001" fullinertia="0.00048519999999999998 0.0016180999999999999 0.0015210499999999999 0 -1.6e-07 -7.5000000000000002e-06"/>
        <!-- <geom name="hip_yaw_link_l_collision" class="unused" type="mesh" group="3" friction="1 0.0050000000000000001 0.0001" pos="-2.7755575615628914e-17 -1.7347234759768071e-17 -6.9388939039072284e-18" euler="0 -0 0" mesh="hip_yaw_link_l"/> -->
        <geom name="hip_yaw_link_l_visual" class="unused" type="mesh" contype="0" conaffinity="0" group="0" pos="-2.7755575615628914e-17 -1.7347234759768071e-17 -6.9388939039072284e-18" euler="0 -0 0" mesh="hip_yaw_link_l"/>
        <joint name="hip_yaw_l" class="bear" type="hinge" pos="-2.7755575615628914e-17 -1.7347234759768071e-17 -6.9388939039072284e-18" axis="0 0 1" limited="true" range="-179.99469134034814 179.99469134034814"  />
        <body name="hip_pitch_link_l" pos="-2.7755575615628914e-17 -1.7347234759768071e-17 -6.9388939039072284e-18" euler="179.99999999755093 89.999789541765594 179.99999999755093">
          <inertial pos="0 6.9999999999999999e-06 0" mass="0.050000000000000003" fullinertia="1.0000000000000001e-05 1.0000000000000001e-05 1.0000000000000001e-05 0 0 0"/>
          <!-- <geom name="hip_pitch_link_l_collision" class="unused" type="mesh" group="3" friction="1 0.0050000000000000001 0.0001" pos="1.3877787807814457e-17 -1.0408340855860843e-17 -1.3877787807814457e-17" euler="0 -0 0" mesh="hip_pitch_link_l"/> -->
          <geom name="hip_pitch_link_l_visual" class="unused" type="mesh" contype="0" conaffinity="0" group="0" pos="1.3877787807814457e-17 -1.0408340855860843e-17 -1.3877787807814457e-17" euler="0 -0 0" mesh="hip_pitch_link_l"/>
          <joint name="hip_pitch_l" class="bear" type="hinge" pos="1.3877787807814457e-17 -1.0408340855860843e-17 -1.3877787807814457e-17" axis="0 0 1" limited="true" range="-179.99469134034814 179.99469134034814"  />
          <body name="hip_roll_link_l" pos="1.3877787807814457e-17 -1.0408340855860843e-17 -1.3877787807814457e-17" euler="-90.000210459149713 -2.6039853883801605e-15 -1.5387972356333047e-14">
            <inertial pos="0.13900000000000001 -0.00037300000000000001 -0.0064900000000000001" mass="0.66351899999999997" fullinertia="0.00044200000000000001 0.016 0.015699999999999999 -7.2899999999999997e-05 -0.00029100000000000003 -1.11e-06"/>
            <!-- <geom name="hip_roll_link_l_collision" class="unused" type="mesh" group="3" friction="1 0.0050000000000000001 0.0001" pos="6.9388939039072284e-18 0 4.163336342344337e-17" euler="0 -1.6810236079381462e-15 0" mesh="hip_roll_link_l"/> -->
            <geom name="hip_roll_link_l_visual" class="unused" type="mesh" contype="0" conaffinity="0" group="0" pos="6.9388939039072284e-18 0 4.163336342344337e-17" euler="0 -1.6810236079381462e-15 0" mesh="hip_roll_link_l"/>
            <joint name="hip_roll_l" class="bear" type="hinge" pos="6.9388939039072284e-18 0 4.163336342344337e-17" axis="-5.8678793524549883e-17 0 1" limited="true" range="-179.99469134034814 179.99469134034814"  />
            <body name="knee_pitch_link_l" pos="0.20494900000000005 -1.3877787807814457e-17 5.2041704279304213e-17" euler="90.000210459149727 -4.5895581906790892e-15 2.588769693899923e-20">
              <inertial pos="0.073099999999999998 0.017809999999999999 -0.0021979999999999999" mass="0.0952654" fullinertia="0.00010799 0.00101705 0.0010792 5.2599999999999998e-05 -1.7399999999999999e-05 6.0700000000000003e-06"/>
              <!-- <geom name="knee_pitch_link_l_collision" class="unused" type="mesh" group="3" friction="1 0.0050000000000000001 0.0001" pos="1.9428902930940239e-16 -7.6327832942979512e-17 1.6653345369377348e-16" euler="0 0 -3.1805546814635168e-15" mesh="knee_pitch_link_l"/> -->
              <geom name="knee_pitch_link_l_visual" class="unused" type="mesh" contype="0" conaffinity="0" group="0" pos="1.9428902930940239e-16 -7.6327832942979512e-17 1.6653345369377348e-16" euler="0 0 -3.1805546814635168e-15" mesh="knee_pitch_link_l"/>
              <joint name="knee_pitch_l" class="bear" type="hinge" pos="1.9428902930940239e-16 -7.6327832942979512e-17 1.6653345369377348e-16" axis="0 0 1" limited="true" range="-179.99469134034814 -0.57295779513082323"  />
              <body name="ankle_pitch_link_l" pos="0.19988100000000017 -7.6327832942979512e-17 1.8041124150158794e-16" euler="0 0 0">
                <inertial pos="0.01234 0.0025300000000000001 -0.00030400000000000002" mass="0.027482900000000001" fullinertia="2.0400000000000001e-05 6.2700000000000001e-06 2.5999999999999998e-05 2.9100000000000001e-06 2.9999999999999997e-08 2.3999999999999998e-07"/>
                <!-- <geom name="ankle_pitch_link_l_collision" class="unused" type="mesh" group="3" friction="1 0.0050000000000000001 0.0001" pos="3.3306690738754696e-16 -5.5511151231257827e-17 4.0245584642661925e-16" euler="0 0 -3.1805546814635168e-15" mesh="ankle_pitch_link_l"/> -->
                <!-- <geom name="l_collision_fl" class="friction_body" type="sphere" group="0" size="0.001" pos="0.024  0.055   0.014" euler="0 0 0"/> -->
                <!-- <geom name="l_collision_bl" class="friction_body" type="sphere" group="0" size="0.001" pos="0.024 -0.045  0.014" euler="0 0 0"/> -->
                <!-- <geom name="l_collision_fr" class="friction_body" type="sphere" group="0" size="0.001" pos="0.024  0.055  -0.014" euler="0 0 0"/> -->
                <!-- <geom name="l_collision_br" class="friction_body" type="sphere" group="0" size="0.001" pos="0.024 -0.045 -0.014" euler="0 0 0"/> -->
               
                <geom name="left_foot_collision" class="friction_body"  type="box" size="0.0515 0.014 0.0035" pos="0.0215 0.005 0.0" euler="90 0 90"/>
                <geom name="ankle_pitch_link_l_visual" class="unused" type="mesh" contype="0" conaffinity="0" group="0" pos="3.3306690738754696e-16 -5.5511151231257827e-17 4.0245584642661925e-16" euler="0 0 -3.1805546814635168e-15" mesh="ankle_pitch_link_l"/>
                <site name="2" size="0.02" group="3" class="unused" pos="0.025 0.05 0" euler="0 0 0"/>
                <site name="midfoot_l" pos="0.025 0.0 0.0"  size="0.01" type="sphere"/>
                <site name="3" size="0.02" group="3" class="unused" pos="0.025 -0.035 0" euler="0 0 0"/>
                <joint name="ankle_pitch_l" class="bear" type="hinge" pos="3.3306690738754696e-16 -5.5511151231257827e-17 4.0245584642661925e-16" axis="0 0 1" limited="true" range="-179.99469134034814 179.99469134034814"  />
                <body name="achilles_rod_l" pos="0 -0.03 0" euler="0 0 0">
                  <inertial pos="-0.1 0.0 0.0" mass="0.00550849" diaginertia="3.1462e-8 1e-4 1e-4"/>
                  <joint name="ankle_achilles_jt_l" class="bear" type="hinge" pos="0 0 0" axis="0 0 1" limited="true" range="-179.99469134034814 179.99469134034814"/>
                  <geom name="achilles_rod_l" class="unused"  type="cylinder" size="0.006" fromto="0.0 0.0 0.0 -0.2 0.0 0.0" euler="90 0 90" contype="0" conaffinity="0"/>
                  <site name="achilles_attach_l" group="3" pos="-0.2 0.0 0.0"  size="0.01" type="sphere"/>
                </body>
              </body>
            </body>
            <body name="ankle_drive_arm_l" pos="0.204949 0.0 0.0" euler="90.0 0 0">
                <!-- The geom for visualization is offset to the side to look like the real robot, but the mechanism is defined in the midplane of the foot to avoid having to create ball joints -->
                <geom name="ankle_pitch_drive_arm_l_visual" class="unused" contype="0" conaffinity="0" type="mesh" group="0" pos="0 0 -0.02625" euler="0 180 -40" mesh="ankle_drive_arm_l"/>
                <inertial pos="0.00052293  0.00264346 0.00113556" mass="0.00832597" fullinertia="1.2724e-6 4.1068e-7 1.6054e-6 7.1971e-8 9.7107e-9 4.3047e-8"/>
                <joint name="ankle_crank_l" class="bear" type="hinge" pos="0 0 0" axis="0 0 1" limited="true" range="-179.99469134034814 179.99469134034814"  />
                <site name="ankle_upper_attach_l" group="0" pos="0.0 -0.03 0.0"  size="0.01" type="sphere"/>
            </body>
          </body>
        </body>
      </body>

      <!-- <body name="shoulder_pitch_link_r" pos="0.029215999999999999 -0.12375 0.15298500000000001" euler="-89.999789540083242 -89.999789541765594 180">
        <geom name="shoulder_pitch_link_r_visual" mass="0.0001" class="unused" type="mesh" contype="0" conaffinity="0" group="0" pos="0 3.8163916471489756e-17 0" euler="0 -0 0" mesh="shoulder_pitch_link_r"/>
        <joint name="shoulder_pitch_r" class="dynamixel" type="hinge" pos="0 3.8163916471489756e-17 0" axis="0 0 1" limited="true" range="-179.99469134034814 179.99469134034814"  />
        <body name="shoulder_roll_link_r" pos="0 3.8163916471489756e-17 0" euler="-89.999789540083242 -89.999789538302082 180">
          <geom name="shoulder_roll_link_r_visual" mass="0.0001" class="unused" type="mesh" contype="0" conaffinity="0" group="0" pos="1.3877787807814457e-17 0 -1.3877787807814457e-17" euler="0 3.180554681463516e-15 0" mesh="shoulder_roll_link_r"/>
          <joint name="shoulder_roll_r" class="dynamixel" type="hinge" pos="1.3877787807814457e-17 0 -1.3877787807814457e-17" axis="1.1102230246251565e-16 0 1" limited="true" range="-179.99469134034814 179.99469134034814"  />
          <body name="elbow_pitch_link_r" pos="0.11460000000000002 -0.0050000000000000044 0.0049999999999999767" euler="90.000210459149727 6.5571044696735299e-15 -2.4388550995442297e-15">
            <geom name="elbow_pitch_link_r_visual" mass="0.0001" class="unused" type="mesh" contype="0" conaffinity="0" group="0" pos="2.7755575615628914e-17 6.9388939039072284e-17 0" euler="0 4.8531412986198681e-20 0" mesh="elbow_pitch_link_r"/>
            <joint name="elbow_pitch_r" class="dynamixel" type="hinge" pos="2.7755575615628914e-17 6.9388939039072284e-17 0" axis="1.6940658945086007e-21 0 1" limited="true" range="-179.99469134034814 179.99469134034814"  />
          </body>
        </body>
      </body>
      <body name="shoulder_pitch_link_l" pos="0.029215999999999999 0.12375 0.15298500000000001" euler="89.999789540083242 89.999789541765594 180">
        <geom name="shoulder_pitch_link_l_visual" mass="0.0001" class="unused" type="mesh" contype="0" conaffinity="0" group="0" pos="-2.7755575615628914e-17 -5.2041704279304213e-17 -1.3877787807814457e-17" euler="0 -0 0" mesh="shoulder_pitch_link_l"/>
        <joint name="shoulder_pitch_l" class="dynamixel" type="hinge" pos="-2.7755575615628914e-17 -5.2041704279304213e-17 -1.3877787807814457e-17" axis="0 0 1" limited="true" range="-179.99469134034814 179.99469134034814"  />
        <body name="shoulder_roll_link_l" pos="-2.7755575615628914e-17 -5.2041704279304213e-17 -1.3877787807814457e-17" euler="-89.999789538351479 -89.999789540033831 179.99999999826824">
          <geom name="shoulder_roll_link_l_visual" mass="0.0001" class="unused" type="mesh" contype="0" conaffinity="0" group="0" pos="1.3877787807814457e-17 2.7755575615628914e-17 -3.4694469519536142e-17" euler="0 -0 0" mesh="shoulder_roll_link_l"/>
          <joint name="shoulder_roll_l" class="dynamixel" type="hinge" pos="1.3877787807814457e-17 2.7755575615628914e-17 -3.4694469519536142e-17" axis="0 0 1" limited="true" range="-179.99469134034814 179.99469134034814"  />
          <body name="elbow_pitch_link_l" pos="0.11459999999999999 0.0050000000000000044 0.0049999999999999906" euler="-90.000210459149713 1.4198072913902969e-15 -1.4198125066432634e-15">
            <geom name="elbow_pitch_link_l_visual" mass="0.0001" class="unused" type="mesh" contype="0" conaffinity="0" group="0" pos="-2.7755575615628914e-17 -4.163336342344337e-17 -2.7755575615628914e-17" euler="0 -0 0" mesh="elbow_pitch_link_l"/>
            <joint name="elbow_pitch_l" class="dynamixel" type="hinge" pos="-2.7755575615628914e-17 -4.163336342344337e-17 -2.7755575615628914e-17" axis="0 0 1" limited="true" range="-179.99469134034814 179.99469134034814"  />
          </body>
        </body>
      </body>-->
    </body> 

  </worldbody>

  <equality>
    <connect site1='ankle_upper_attach_l'  site2='achilles_attach_l'/>
    <connect site1='ankle_upper_attach_r'  site2='achilles_attach_r'/>
  </equality>

  <!-- <contact>
    <pair name="r_collision_floor" geom1="right_foot_collision" geom2="plane" condim="3"/>
    <pair name="l_collision_floor" geom1="left_foot_collision" geom2="plane" condim="3"/>
  </contact> -->

  <!--Sim gains for sim-dt = 0.004-->
  <actuator>
    <position class="bear" kp="80" joint="hip_yaw_r"      name="hip_yaw_r_pos"/>
    <position class="bear" kp="80" joint="hip_pitch_r"    name="hip_pitch_r_pos"/>
    <position class="bear" kp="80" joint="hip_roll_r"     name="hip_roll_r_pos"/>
    <position class="bear" kp="80" joint="knee_pitch_r"   name="knee_pitch_r_pos"/>
    <position class="bear" kp="80"  joint="ankle_crank_r" name="ankle_crank_r_pos"/>

    <position class="bear" kp="80" joint="hip_yaw_l"      name="hip_yaw_l_pos"/>
    <position class="bear" kp="80" joint="hip_pitch_l"    name="hip_pitch_l_pos"/>
    <position class="bear" kp="80" joint="hip_roll_l"     name="hip_roll_l_pos"/>
    <position class="bear" kp="80" joint="knee_pitch_l"   name="knee_pitch_l_pos"/>
    <position class="bear" kp="80"  joint="ankle_crank_l" name="ankle_crank_l_pos"/>

    <!-- <position name="shoulder_pitch_r_pos"  joint="shoulder_pitch_r" kp="0" forcerange="-5 5" />
    <position name="shoulder_roll_r_pos"   joint="shoulder_roll_r"  kp="0" forcerange="-5 5" />
    <position name="elbow_pitch_r_pos"     joint="elbow_pitch_r"    kp="0" forcerange="-5 5" />
    <position name="shoulder_pitch_l_pos"  joint="shoulder_pitch_l" kp="0" forcerange="-5 5" />
    <position name="shoulder_roll_l_pos"   joint="shoulder_roll_l"  kp="0" forcerange="-5 5" />
    <position name="elbow_pitch_l_pos"     joint="elbow_pitch_l"    kp="0" forcerange="-5 5" /> -->

    <velocity kv="2" joint="hip_yaw_r"     name="hip_yaw_r_vel"/>
    <velocity kv="2" joint="hip_pitch_r"   name="hip_pitch_r_vel"/>
    <velocity kv="2" joint="hip_roll_r"    name="hip_roll_r_vel"/>
    <velocity kv="2" joint="knee_pitch_r"  name="knee_pitch_r_vel"/>
    <velocity kv="2" joint="ankle_crank_r" name="ankle_crank_r_vel"/>
    <velocity kv="2" joint="hip_yaw_l"     name="hip_yaw_l_vel"/>
    <velocity kv="2" joint="hip_pitch_l"   name="hip_pitch_l_vel"/>
    <velocity kv="2" joint="hip_roll_l"    name="hip_roll_l_vel"/>
    <velocity kv="2" joint="knee_pitch_l"  name="knee_pitch_l_vel"/>
    <velocity kv="2" joint="ankle_crank_l" name="ankle_crank_l_vel"/>

    <!-- <velocity name="shoulder_pitch_r_vel" joint="shoulder_pitch_r" kv="0" forcerange="-5 5" />
    <velocity name="shoulder_roll_r_vel"  joint="shoulder_roll_r"  kv="0" forcerange="-5 5" />
    <velocity name="elbow_pitch_r_vel"    joint="elbow_pitch_r"    kv="0" forcerange="-5 5" />
    <velocity name="shoulder_pitch_l_vel" joint="shoulder_pitch_l" kv="0" forcerange="-5 5" />
    <velocity name="shoulder_roll_l_vel"  joint="shoulder_roll_l"  kv="0" forcerange="-5 5" />
    <velocity name="elbow_pitch_l_vel"    joint="elbow_pitch_l"    kv="0" forcerange="-5 5" /> -->
  </actuator>
  
  <sensor>
    <touch name="opto1" site="0"/>
    <touch name="opto2" site="1"/>
    <touch name="opto3" site="2"/>
    <touch name="opto4" site="3"/>
    <gyro name="base_gyro" site="base_IMU"/>
    <accelerometer name="base_accelerometer" site="base_IMU"/>
    <framexaxis name="left_foot_z" objtype="site" objname="midfoot_l"/>
    <framexaxis name="right_foot_z" objtype="site" objname="midfoot_r"/>
    <framepos name="right_foot" objtype='site' objname='midfoot_r'/>
    <framepos name="left_foot" objtype='site' objname='midfoot_l'/>
    <framelinvel name="right_foot_vel" objtype='site' objname='midfoot_r'/>
    <framelinvel name="left_foot_vel" objtype='site' objname='midfoot_l'/>
    <velocimeter name="base_velocimeter" site="base_IMU"/>
  </sensor>

</mujoco>
